Workbook

Sheet Planilha1
A1: 44912 | B1: ESTRUTURA | C1: 831-H22-000-002-0 | D1: BÁSICO | E1: =LEFT(C1,15) -> 831-H22-000-002 | F1: =VLOOKUP(E1,DWG_TITLES!A:B,2,FALSE) -> FREEBOARD PLAN
A2: 44956 | B2: ESTRUTURA | C2: 831-H22-000-002-A | D2: BÁSICO | E2: =LEFT(C2,15) -> 831-H22-000-002 | F2: =VLOOKUP(E2,DWG_TITLES!A:B,2,FALSE) -> FREEBOARD PLAN
A3: 45122 | B3: ESTRUTURA | C3: 831-H22-000-002-B | D3: BÁSICO | E3: =LEFT(C3,15) -> 831-H22-000-002 | F3: =VLOOKUP(E3,DWG_TITLES!A:B,2,FALSE) -> FREEBOARD PLAN
A4: 45985 | B4: ESTRUTURA | C4: 831-H22-000-002-D | D4: BÁSICO | E4: =LEFT(C4,15) -> 831-H22-000-002 | F4: =VLOOKUP(E4,DWG_TITLES!A:B,2,FALSE) -> FREEBOARD PLAN
A5: 44879 | B5: ESTRUTURA | C5: 831-H22-000-003-0 | D5: BÁSICO | E5: =LEFT(C5,15) -> 831-H22-000-003 | F5: =VLOOKUP(E5,DWG_TITLES!A:B,2,FALSE) -> BLOCK DIVISION
A6: 44887 | B6: ESTRUTURA | C6: 831-H22-000-003-A | D6: BÁSICO | E6: =LEFT(C6,15) -> 831-H22-000-003 | F6: =VLOOKUP(E6,DWG_TITLES!A:B,2,FALSE) -> BLOCK DIVISION
A7: 44905 | B7: ESTRUTURA | C7: 831-H22-000-003-B | D7: BÁSICO | E7: =LEFT(C7,15) -> 831-H22-000-003 | F7: =VLOOKUP(E7,DWG_TITLES!A:B,2,FALSE) -> BLOCK DIVISION
A8: 44965 | B8: ESTRUTURA | C8: 831-H22-000-003-C | D8: BÁSICO | E8: =LEFT(C8,15) -> 831-H22-000-003 | F8: =VLOOKUP(E8,DWG_TITLES!A:B,2,FALSE) -> BLOCK DIVISION
A9: 45028 | B9: ESTRUTURA | C9: 831-H22-000-003-D | D9: BÁSICO | E9: =LEFT(C9,15) -> 831-H22-000-003 | F9: =VLOOKUP(E9,DWG_TITLES!A:B,2,FALSE) -> BLOCK DIVISION
A10: 45127 | B10: ESTRUTURA | C10: 831-H22-077-001-0 | D10: BÁSICO | E10: =LEFT(C10,15) -> 831-H22-077-001 | F10: =VLOOKUP(E10,DWG_TITLES!A:B,2,FALSE) -> LIFE SAVING APPLIANCE AND EVACUATION PLAN
A11: 45168 | B11: ESTRUTURA | C11: 831-H22-077-001-A | D11: BÁSICO | E11: =LEFT(C11,15) -> 831-H22-077-001 | F11: =VLOOKUP(E11,DWG_TITLES!A:B,2,FALSE) -> LIFE SAVING APPLIANCE AND EVACUATION PLAN
A12: 45213 | B12: ESTRUTURA | C12: 831-H22-077-001-B | D12: BÁSICO | E12: =LEFT(C12,15) -> 831-H22-077-001 | F12: =VLOOKUP(E12,DWG_TITLES!A:B,2,FALSE) -> LIFE SAVING APPLIANCE AND EVACUATION PLAN
... A844: 46129 | B844: ESTRUTURA | C844: 831-H22-997-001-E | D844: BÁSICO | E844: =LEFT(C844,15) -> 831-H22-997-001 | F844: =VLOOKUP(E844,DWG_TITLES!A:B,2,FALSE) -> DOCKING PLAN
A845: 44945 | B845: ESTRUTURA | C845: 831-PS-H22-996-001-0 | D845: BÁSICO | E845: =LEFT(C845,18) -> 831-PS-H22-996-001 | F845: =VLOOKUP(E845,DWG_TITLES!A:B,2,FALSE) -> OFFLOADING
A846: 45127 | B846: ESTRUTURA | C846: 831-PS-H22-996-001-A | D846: BÁSICO | E846: =LEFT(C846,18) -> 831-PS-H22-996-001 | F846: =VLOOKUP(E846,DWG_TITLES!A:B,2,FALSE) -> OFFLOADING
A847: 46163 | B847: EIT | C847: 832-7-H22-063-001-0 | D847: BÁSICO | E847: =LEFT(C847,17) -> 832-7-H22-063-001 | F847: =VLOOKUP(E847,DWG_TITLES!A:B,2,FALSE) -> ACQUISITION SPECIFICATION OF CABLE REEL
A848: 46230 | B848: EIT | C848: 832-7-H22-063-001-A | D848: BÁSICO | E848: =LEFT(C848,17) -> 832-7-H22-063-001 | F848: =VLOOKUP(E848,DWG_TITLES!A:B,2,FALSE) -> ACQUISITION SPECIFICATION OF CABLE REEL
A849: 45000 | B849: ELÉTRICA | C849: 832-7-H22-123-001-0 | D849: BÁSICO | E849: =LEFT(C849,17) -> 832-7-H22-123-001 | F849: =VLOOKUP(E849,DWG_TITLES!A:B,2,FALSE) -> ACQUISITION SPECIFICATION - REMOTE TANK LEVEL TRANSMITTER
A850: 45028 | B850: ELÉTRICA | C850: 832-7-H22-123-001-A | D850: BÁSICO | E850: =LEFT(C850,17) -> 832-7-H22-123-001 | F850: =VLOOKUP(E850,DWG_TITLES!A:B,2,FALSE) -> ACQUISITION SPECIFICATION - REMOTE TANK LEVEL TRANSMITTER
A851: 45076 | B851: ELÉTRICA | C851: 832-7-H22-123-001-B | D851: BÁSICO | E851: =LEFT(C851,17) -> 832-7-H22-123-001 | F851: =VLOOKUP(E851,DWG_TITLES!A:B,2,FALSE) -> ACQUISITION SPECIFICATION - REMOTE TANK LEVEL TRANSMITTER
A852: 45105 | B852: ELÉTRICA | C852: 832-7-H22-123-001-C | D852: BÁSICO | E852: =LEFT(C852,17) -> 832-7-H22-123-001 | F852: =VLOOKUP(E852,DWG_TITLES!A:B,2,FALSE) -> ACQUISITION SPECIFICATION - REMOTE TANK LEVEL TRANSMITTER
A853: 45128 | B853: ELÉTRICA | C853: 832-7-H22-123-001-D | D853: BÁSICO | E853: =LEFT(C853,17) -> 832-7-H22-123-001 | F853: =VLOOKUP(E853,DWG_TITLES!A:B,2,FALSE) -> ACQUISITION SPECIFICATION - REMOTE TANK LEVEL TRANSMITTER
A854: 46080 | B854: ELÉTRICA | C854: 832-7-H22-123-001-F | D854: BÁSICO | E854: =LEFT(C854,17) -> 832-7-H22-123-001 | F854: =VLOOKUP(E854,DWG_TITLES!A:B,2,FALSE) -> ACQUISITION SPECIFICATION - REMOTE TANK LEVEL TRANSMITTER
A855: 45236 | B855: ELÉTRICA | C855: 832-7-H22-123-002-0 | D855: BÁSICO | E855: =LEFT(C855,17) -> 832-7-H22-123-002 | F855: =VLOOKUP(E855,DWG_TITLES!A:B,2,FALSE) -> TECHNICAL BID EVALUATION - REMOTE TANK LEVEL TRANSMITTER
A856: 45239 | B856: ELÉTRICA | C856: 832-7-H22-123-002-B | D856: BÁSICO | E856: =LEFT(C856,17) -> 832-7-H22-123-002 | F856: =VLOOKUP(E856,DWG_TITLES!A:B,2,FALSE) -> TECHNICAL BID EVALUATION - REMOTE TANK LEVEL TRANSMITTER
A857: 44959 | B857: ARQUITETURA | C857: 832-7-H22-160-001-0 | D857: BÁSICO | E857: =LEFT(C857,17) -> 832-7-H22-160-001 | F857: =VLOOKUP(E857,DWG_TITLES!A:B,2,FALSE) -> ACQUISITION SPECIFICATION - HELIDECK SAFETY NET
A858: 44960 | B858: ARQUITETURA | C858: 832-7-H22-160-001-A | D858: BÁSICO | E858: =LEFT(C858,17) -> 832-7-H22-160-001 | F858: =VLOOKUP(E858,DWG_TITLES!A:B,2,FALSE) -> ACQUISITION SPECIFICATION - HELIDECK SAFETY NET
... A1565: 45523 | B1565: MECÂNICA | C1565: 832-7-H22-850-001-G | D1565: BÁSICO | E1565: =LEFT(C1565,17) -> 832-7-H22-850-001 | F1565: =VLOOKUP(E1565,DWG_TITLES!A:B,2,FALSE) -> CANCELADO - PIPING SPECIFICATION
A1566: 44914 | B1566: MECÂNICA | C1566: 832-TBE-H22-200-001-0 | D1566: BÁSICO | E1566: =LEFT(C1566,19) -> 832-TBE-H22-200-001 | F1566: =VLOOKUP(E1566,DWG_TITLES!A:B,2,FALSE) -> CANCELADO - TECHNICAL BID EVALUATION - PROPULSION SYSTEM
A1567: 44980 | B1567: MECÂNICA | C1567: 832-TBE-H22-200-001-A | D1567: BÁSICO | E1567: =LEFT(C1567,19) -> 832-TBE-H22-200-001 | F1567: =VLOOKUP(E1567,DWG_TITLES!A:B,2,FALSE) -> CANCELADO - TECHNICAL BID EVALUATION - PROPULSION SYSTEM
A1568: 44998 | B1568: MECÂNICA | C1568: 832-TBE-H22-200-001-B | D1568: BÁSICO | E1568: =LEFT(C1568,19) -> 832-TBE-H22-200-001 | F1568: =VLOOKUP(E1568,DWG_TITLES!A:B,2,FALSE) -> CANCELADO - TECHNICAL BID EVALUATION - PROPULSION SYSTEM
A1569: 45042 | B1569: MECÂNICA | C1569: 832-TBE-H22-200-001-C | D1569: BÁSICO | E1569: =LEFT(C1569,19) -> 832-TBE-H22-200-001 | F1569: =VLOOKUP(E1569,DWG_TITLES!A:B,2,FALSE) -> CANCELADO - TECHNICAL BID EVALUATION - PROPULSION SYSTEM
A1570: 45062 | B1570: ELÉTRICA | C1570: 832-TBE-H22-233-001-0 | D1570: BÁSICO | E1570: =LEFT(C1570,19) -> 832-TBE-H22-233-001 | F1570: =VLOOKUP(E1570,DWG_TITLES!A:B,2,FALSE) -> CANCELADO - TECHNICAL BID EVALUATION - INTEGRATED ELECTRIC PROPULSION SYSTEM
A1571: 44908 | B1571: MECÂNICA | C1571: 832-TBE-H22-235-001-0 | D1571: BÁSICO | E1571: =LEFT(C1571,19) -> 832-TBE-H22-235-001 | F1571: =VLOOKUP(E1571,DWG_TITLES!A:B,2,FALSE) -> CANCELADO - TECHNICAL BID EVALUATION - MAIN DIESEL ENGINES
A1572: 44956 | B1572: MECÂNICA | C1572: 832-TBE-H22-235-001-A | D1572: BÁSICO | E1572: =LEFT(C1572,19) -> 832-TBE-H22-235-001 | F1572: =VLOOKUP(E1572,DWG_TITLES!A:B,2,FALSE) -> CANCELADO - TECHNICAL BID EVALUATION - MAIN DIESEL ENGINES
A1573: 44980 | B1573: MECÂNICA | C1573: 832-TBE-H22-235-001-B | D1573: BÁSICO | E1573: =LEFT(C1573,19) -> 832-TBE-H22-235-001 | F1573: =VLOOKUP(E1573,DWG_TITLES!A:B,2,FALSE) -> CANCELADO - TECHNICAL BID EVALUATION - MAIN DIESEL ENGINES
A1574: 44966 | B1574: MECÂNICA | C1574: 832-TBE-H22-245-001-A | D1574: BÁSICO | E1574: =LEFT(C1574,19) -> 832-TBE-H22-245-001 | F1574: =VLOOKUP(E1574,DWG_TITLES!A:B,2,FALSE) -> CANCELADO - TECHNICAL BID EVALUATION - BOW THRUSTER SYSTEM
A1575: 45000 | B1575: MECÂNICA | C1575: 832-TBE-H22-245-001-B | D1575: BÁSICO | E1575: =LEFT(C1575,19) -> 832-TBE-H22-245-001 | F1575: =VLOOKUP(E1575,DWG_TITLES!A:B,2,FALSE) -> CANCELADO - TECHNICAL BID EVALUATION - BOW THRUSTER SYSTEM
A1576: 44959 | B1576: MECÂNICA | C1576: 832-TBE-H22-245-002-0 | D1576: BÁSICO | E1576: =LEFT(C1576,19) -> 832-TBE-H22-245-002 | F1576: =VLOOKUP(E1576,DWG_TITLES!A:B,2,FALSE) -> CANCELADO - TECHNICAL BID EVALUATION - STERN THRUSTER SYSTEM
A1577: 44909 | B1577: MECÂNICA | C1577: 832-TBE-H22-312-001-0 | D1577: BÁSICO | E1577: =LEFT(C1577,19) -> 832-TBE-H22-312-001 | F1577: =VLOOKUP(E1577,DWG_TITLES!A:B,2,FALSE) -> CANCELADO - TECHNICAL BID EVALUATION - DIESEL GENERATOR SETS, EMERGENCY
...

Sheet Planilha2
A1: 44912 | B1: =VLOOKUP(Planilha1!B1,LANG!A:B,2,FALSE) -> STRUCTURE | C1: 831-H22-000-002-0 | D1: =VLOOKUP(Planilha1!D1,LANG!A:B,2,FALSE) -> BASIC | E1: 831-H22-000-002 | F1: =VLOOKUP(E1,DWG_TITLES!A:B,2,FALSE) -> FREEBOARD PLAN
A2: 44956 | B2: =VLOOKUP(Planilha1!B2,LANG!A:B,2,FALSE) -> STRUCTURE | C2: 831-H22-000-002-A | D2: =VLOOKUP(Planilha1!D2,LANG!A:B,2,FALSE) -> BASIC | E2: 831-H22-000-002 | F2: =VLOOKUP(E2,DWG_TITLES!A:B,2,FALSE) -> FREEBOARD PLAN
A3: 45122 | B3: =VLOOKUP(Planilha1!B3,LANG!A:B,2,FALSE) -> STRUCTURE | C3: 831-H22-000-002-B | D3: =VLOOKUP(Planilha1!D3,LANG!A:B,2,FALSE) -> BASIC | E3: 831-H22-000-002 | F3: =VLOOKUP(E3,DWG_TITLES!A:B,2,FALSE) -> FREEBOARD PLAN
A4: 45985 | B4: =VLOOKUP(Planilha1!B4,LANG!A:B,2,FALSE) -> STRUCTURE | C4: 831-H22-000-002-D | D4: =VLOOKUP(Planilha1!D4,LANG!A:B,2,FALSE) -> BASIC | E4: 831-H22-000-002 | F4: =VLOOKUP(E4,DWG_TITLES!A:B,2,FALSE) -> FREEBOARD PLAN
A5: 44879 | B5: =VLOOKUP(Planilha1!B5,LANG!A:B,2,FALSE) -> STRUCTURE | C5: 831-H22-000-003-0 | D5: =VLOOKUP(Planilha1!D5,LANG!A:B,2,FALSE) -> BASIC | E5: 831-H22-000-003 | F5: =VLOOKUP(E5,DWG_TITLES!A:B,2,FALSE) -> BLOCK DIVISION
A6: 44887 | B6: =VLOOKUP(Planilha1!B6,LANG!A:B,2,FALSE) -> STRUCTURE | C6: 831-H22-000-003-A | D6: =VLOOKUP(Planilha1!D6,LANG!A:B,2,FALSE) -> BASIC | E6: 831-H22-000-003 | F6: =VLOOKUP(E6,DWG_TITLES!A:B,2,FALSE) -> BLOCK DIVISION
A7: 44905 | B7: =VLOOKUP(Planilha1!B7,LANG!A:B,2,FALSE) -> STRUCTURE | C7: 831-H22-000-003-B | D7: =VLOOKUP(Planilha1!D7,LANG!A:B,2,FALSE) -> BASIC | E7: 831-H22-000-003 | F7: =VLOOKUP(E7,DWG_TITLES!A:B,2,FALSE) -> BLOCK DIVISION
A8: 44965 | B8: =VLOOKUP(Planilha1!B8,LANG!A:B,2,FALSE) -> STRUCTURE | C8: 831-H22-000-003-C | D8: =VLOOKUP(Planilha1!D8,LANG!A:B,2,FALSE) -> BASIC | E8: 831-H22-000-003 | F8: =VLOOKUP(E8,DWG_TITLES!A:B,2,FALSE) -> BLOCK DIVISION
A9: 45028 | B9: =VLOOKUP(Planilha1!B9,LANG!A:B,2,FALSE) -> STRUCTURE | C9: 831-H22-000-003-D | D9: =VLOOKUP(Planilha1!D9,LANG!A:B,2,FALSE) -> BASIC | E9: 831-H22-000-003 | F9: =VLOOKUP(E9,DWG_TITLES!A:B,2,FALSE) -> BLOCK DIVISION
A10: 45127 | B10: =VLOOKUP(Planilha1!B10,LANG!A:B,2,FALSE) -> STRUCTURE | C10: 831-H22-077-001-0 | D10: =VLOOKUP(Planilha1!D10,LANG!A:B,2,FALSE) -> BASIC | E10: 831-H22-077-001 | F10: =VLOOKUP(E10,DWG_TITLES!A:B,2,FALSE) -> LIFE SAVING APPLIANCE AND EVACUATION PLAN
A11: 45168 | B11: =VLOOKUP(Planilha1!B11,LANG!A:B,2,FALSE) -> STRUCTURE | C11: 831-H22-077-001-A | D11: =VLOOKUP(Planilha1!D11,LANG!A:B,2,FALSE) -> BASIC | E11: 831-H22-077-001 | F11: =VLOOKUP(E11,DWG_TITLES!A:B,2,FALSE) -> LIFE SAVING APPLIANCE AND EVACUATION PLAN
A12: 45213 | B12: =VLOOKUP(Planilha1!B12,LANG!A:B,2,FALSE) -> STRUCTURE | C12: 831-H22-077-001-B | D12: =VLOOKUP(Planilha1!D12,LANG!A:B,2,FALSE) -> BASIC | E12: 831-H22-077-001 | F12: =VLOOKUP(E12,DWG_TITLES!A:B,2,FALSE) -> LIFE SAVING APPLIANCE AND EVACUATION PLAN
... A12993: 46273 | B12993: =VLOOKUP(Planilha1!B12993,LANG!A:B,2,FALSE) -> STRUCTURE | C12993: 831-H22-100-132-A-INFALT 01A | D12993: =VLOOKUP(Planilha1!D12993,LANG!A:B,2,FALSE) -> INFALT | E12993: 831-H22-100-132 | F12993: =VLOOKUP(E12993,DWG_TITLES!A:B,2,FALSE) -> PADRÃO DE CHAPA CURVA BLOCO 05 - SUB BLOCO 108

Sheet ADP_PT
A1: 44973 | B1: ESTRUTURA | C1: ADP-E0332-0025 | D1: BÁSICO | E1: APROVADO C/ RNC | F1: =VLOOKUP(C1,DWG_TITLES!A:B,2,FALSE) -> FREEBOARD PLAN
A2: 45238 | B2: ESTRUTURA | C2: ADP-E3324-0204 | D2: BÁSICO | E2: APROVADO | F2: =VLOOKUP(C2,DWG_TITLES!A:B,2,FALSE) -> FREEBOARD PLAN
A3: 45853 | B3: ESTRUTURA | C3: ADP-E3325-0236 | D3: BÁSICO | E3: APROVADO C/ RNC | F3: =VLOOKUP(C3,DWG_TITLES!A:B,2,FALSE) -> FREEBOARD PLAN
A4: 46001 | B4: ESTRUTURA | C4: ADP-E3325-0306 | D4: BÁSICO | E4: APROVADO | F4: =VLOOKUP(C4,DWG_TITLES!A:B,2,FALSE) -> FREEBOARD PLAN
A5: 45278 | B5: ESTRUTURA | C5: ADP-E3324-0231 | D5: BÁSICO | E5: APROVADO | F5: =VLOOKUP(C5,DWG_TITLES!A:B,2,FALSE) -> BLOCK DIVISION
A6: 45727 | B6: ESTRUTURA | C6: ADP-E3325-0207 | D6: BÁSICO | E6: APROVADO | F6: =VLOOKUP(C6,DWG_TITLES!A:B,2,FALSE) -> BLOCK DIVISION
A7: 45139 | B7: ESTRUTURA | C7: ADP-E0332-0160 | D7: BÁSICO | E7: NÃO APROVADO | F7: =VLOOKUP(C7,DWG_TITLES!A:B,2,FALSE) -> LIFE SAVING APPLIANCE AND EVACUATION PLAN
A8: 45201 | B8: ESTRUTURA | C8: ADP-E3324-0189 | D8: BÁSICO | E8: NÃO APROVADO | F8: =VLOOKUP(C8,DWG_TITLES!A:B,2,FALSE) -> LIFE SAVING APPLIANCE AND EVACUATION PLAN
A9: 45260 | B9: ESTRUTURA | C9: ADP-E3321-0054 | D9: BÁSICO | E9: NÃO APROVADO | F9: =VLOOKUP(C9,DWG_TITLES!A:B,2,FALSE) -> LIFE SAVING APPLIANCE AND EVACUATION PLAN
A10: 45399 | B10: ESTRUTURA | C10: ADP-E3321-0111 | D10: BÁSICO | E10: APROVADO C/ RNC | F10: =VLOOKUP(C10,DWG_TITLES!A:B,2,FALSE) -> LIFE SAVING APPLIANCE AND EVACUATION PLAN
A11: 45838 | B11: ESTRUTURA | C11: ADP-E3325-0222 | D11: BÁSICO | E11: NÃO APROVADO | F11: =VLOOKUP(C11,DWG_TITLES!A:B,2,FALSE) -> LIFE SAVING APPLIANCE AND EVACUATION PLAN
A12: 46114 | B12: ESTRUTURA | C12: ADP-E3325-0352 | D12: BÁSICO | E12: NÃO APROVADO | F12: =VLOOKUP(C12,DWG_TITLES!A:B,2,FALSE) -> LIFE SAVING APPLIANCE AND EVACUATION PLAN
... A1146: 45273 | B1146: GERAL | C1146: ADP-E0332-0182 | D1146: DETALHADO | E1146: APROVADO C/ RNC | F1146: =VLOOKUP(C1146,DWG_TITLES!A:B,2,FALSE) -> MAQUETE 3D DO NAVIO EM NAVISWORKS

Sheet ADP_EN
A1: 44973 | B1: =VLOOKUP(ADP_PT!B1,LANG!A:B,2,FALSE) -> STRUCTURE | C1: ADP-E0332-0025 | D1: BASIC | E1: =VLOOKUP(ADP_PT!E1,LANG!A:B,2,FALSE) -> APPROVED WITH RNC | F1: =VLOOKUP(C1,DWG_TITLES!A:B,2,FALSE) -> FREEBOARD PLAN
A2: 45238 | B2: =VLOOKUP(ADP_PT!B2,LANG!A:B,2,FALSE) -> STRUCTURE | C2: ADP-E3324-0204 | D2: BASIC | E2: =VLOOKUP(ADP_PT!E2,LANG!A:B,2,FALSE) -> APPROVED | F2: =VLOOKUP(C2,DWG_TITLES!A:B,2,FALSE) -> FREEBOARD PLAN
A3: 45853 | B3: =VLOOKUP(ADP_PT!B3,LANG!A:B,2,FALSE) -> STRUCTURE | C3: ADP-E3325-0236 | D3: BASIC | E3: =VLOOKUP(ADP_PT!E3,LANG!A:B,2,FALSE) -> APPROVED WITH RNC | F3: =VLOOKUP(C3,DWG_TITLES!A:B,2,FALSE) -> FREEBOARD PLAN
A4: 46001 | B4: =VLOOKUP(ADP_PT!B4,LANG!A:B,2,FALSE) -> STRUCTURE | C4: ADP-E3325-0306 | D4: BASIC | E4: =VLOOKUP(ADP_PT!E4,LANG!A:B,2,FALSE) -> APPROVED | F4: =VLOOKUP(C4,DWG_TITLES!A:B,2,FALSE) -> FREEBOARD PLAN
A5: 45278 | B5: =VLOOKUP(ADP_PT!B5,LANG!A:B,2,FALSE) -> STRUCTURE | C5: ADP-E3324-0231 | D5: BASIC | E5: =VLOOKUP(ADP_PT!E5,LANG!A:B,2,FALSE) -> APPROVED | F5: =VLOOKUP(C5,DWG_TITLES!A:B,2,FALSE) -> BLOCK DIVISION
A6: 45727 | B6: =VLOOKUP(ADP_PT!B6,LANG!A:B,2,FALSE) -> STRUCTURE | C6: ADP-E3325-0207 | D6: BASIC | E6: =VLOOKUP(ADP_PT!E6,LANG!A:B,2,FALSE) -> APPROVED | F6: =VLOOKUP(C6,DWG_TITLES!A:B,2,FALSE) -> BLOCK DIVISION
A7: 45139 | B7: =VLOOKUP(ADP_PT!B7,LANG!A:B,2,FALSE) -> STRUCTURE | C7: ADP-E0332-0160 | D7: BASIC | E7: =VLOOKUP(ADP_PT!E7,LANG!A:B,2,FALSE) -> NOT APPROVED | F7: =VLOOKUP(C7,DWG_TITLES!A:B,2,FALSE) -> LIFE SAVING APPLIANCE AND EVACUATION PLAN
A8: 45201 | B8: =VLOOKUP(ADP_PT!B8,LANG!A:B,2,FALSE) -> STRUCTURE | C8: ADP-E3324-0189 | D8: BASIC | E8: =VLOOKUP(ADP_PT!E8,LANG!A:B,2,FALSE) -> NOT APPROVED | F8: =VLOOKUP(C8,DWG_TITLES!A:B,2,FALSE) -> LIFE SAVING APPLIANCE AND EVACUATION PLAN
A9: 45260 | B9: =VLOOKUP(ADP_PT!B9,LANG!A:B,2,FALSE) -> STRUCTURE | C9: ADP-E3321-0054 | D9: BASIC | E9: =VLOOKUP(ADP_PT!E9,LANG!A:B,2,FALSE) -> NOT APPROVED | F9: =VLOOKUP(C9,DWG_TITLES!A:B,2,FALSE) -> LIFE SAVING APPLIANCE AND EVACUATION PLAN
A10: 45399 | B10: =VLOOKUP(ADP_PT!B10,LANG!A:B,2,FALSE) -> STRUCTURE | C10: ADP-E3321-0111 | D10: BASIC | E10: =VLOOKUP(ADP_PT!E10,LANG!A:B,2,FALSE) -> APPROVED WITH RNC | F10: =VLOOKUP(C10,DWG_TITLES!A:B,2,FALSE) -> LIFE SAVING APPLIANCE AND EVACUATION PLAN
A11: 45838 | B11: =VLOOKUP(ADP_PT!B11,LANG!A:B,2,FALSE) -> STRUCTURE | C11: ADP-E3325-0222 | D11: BASIC | E11: =VLOOKUP(ADP_PT!E11,LANG!A:B,2,FALSE) -> NOT APPROVED | F11: =VLOOKUP(C11,DWG_TITLES!A:B,2,FALSE) -> LIFE SAVING APPLIANCE AND EVACUATION PLAN
A12: 46114 | B12: =VLOOKUP(ADP_PT!B12,LANG!A:B,2,FALSE) -> STRUCTURE | C12: ADP-E3325-0352 | D12: BASIC | E12: =VLOOKUP(ADP_PT!E12,LANG!A:B,2,FALSE) -> NOT APPROVED | F12: =VLOOKUP(C12,DWG_TITLES!A:B,2,FALSE) -> LIFE SAVING APPLIANCE AND EVACUATION PLAN
... A1146: 45273 | B1146: =VLOOKUP(ADP_PT!B1146,LANG!A:B,2,FALSE) -> GERAL | C1146: ADP-E0332-0182 | D1146: DETAILED | E1146: =VLOOKUP(ADP_PT!E1146,LANG!A:B,2,FALSE) -> APPROVED WITH RNC | F1146: =VLOOKUP(C1146,DWG_TITLES!A:B,2,FALSE) -> MAQUETE 3D DO NAVIO EM NAVISWORKS

Sheet MTO_PT
A1: 46007 | B1: EIT | C1: 831-H22-300-063-0 | D1: DETALHADO | E1: =LEFT(C1,15) -> 831-H22-300-063 | F1: =VLOOKUP(E1,DWG_TITLES!A:B,2,FALSE) -> MATERIAL LIST OF MCTs - SEALING MODULES
A2: 46030 | B2: EIT | C2: 831-H22-300-063-A | D2: DETALHADO | E2: =LEFT(C2,15) -> 831-H22-300-063 | F2: =VLOOKUP(E2,DWG_TITLES!A:B,2,FALSE) -> MATERIAL LIST OF MCTs - SEALING MODULES
A3: 46063 | B3: EIT | C3: 831-H22-300-063-B | D3: DETALHADO | E3: =LEFT(C3,15) -> 831-H22-300-063 | F3: =VLOOKUP(E3,DWG_TITLES!A:B,2,FALSE) -> MATERIAL LIST OF MCTs - SEALING MODULES
A4: 46120 | B4: EIT | C4: 831-H22-300-063-C | D4: DETALHADO | E4: =LEFT(C4,15) -> 831-H22-300-063 | F4: =VLOOKUP(E4,DWG_TITLES!A:B,2,FALSE) -> MATERIAL LIST OF MCTs - SEALING MODULES
A5: 46219 | B5: EIT | C5: 831-H22-300-063-D | D5: DETALHADO | E5: =LEFT(C5,15) -> 831-H22-300-063 | F5: =VLOOKUP(E5,DWG_TITLES!A:B,2,FALSE) -> MATERIAL LIST OF MCTs - SEALING MODULES
A6: 46241 | B6: EIT | C6: EST-H22-300-501-0 | D6: DETALHADO | E6: =LEFT(C6,15) -> EST-H22-300-501 | F6: =VLOOKUP(E6,DWG_TITLES!A:B,2,FALSE) -> OVERALL INSTRUMENT LIST
A7: 46156 | B7: MECÂNICA | C7: LIS-H22-180-001-0 | D7: DETALHADO | E7: =LEFT(C7,15) -> LIS-H22-180-001 | F7: =VLOOKUP(E7,DWG_TITLES!A:B,2,FALSE) -> LISTA DE MATERIAIS PARA ELEMENTOS DE FIXAÇÃO PARA EQUIPAMENTOS MECÂNICOS
A8: 46205 | B8: MECÂNICA | C8: LIS-H22-180-001-A | D8: DETALHADO | E8: =LEFT(C8,15) -> LIS-H22-180-001 | F8: =VLOOKUP(E8,DWG_TITLES!A:B,2,FALSE) -> LISTA DE MATERIAIS PARA ELEMENTOS DE FIXAÇÃO PARA EQUIPAMENTOS MECÂNICOS
A9: 46205 | B9: MECÂNICA | C9: LIS-H22-180-001-B | D9: DETALHADO | E9: =LEFT(C9,15) -> LIS-H22-180-001 | F9: =VLOOKUP(E9,DWG_TITLES!A:B,2,FALSE) -> LISTA DE MATERIAIS PARA ELEMENTOS DE FIXAÇÃO PARA EQUIPAMENTOS MECÂNICOS
A10: 45162 | B10: EIT | C10: LIS-H22-321-001-0 | D10: DETALHADO | E10: =LEFT(C10,15) -> LIS-H22-321-001 | F10: =VLOOKUP(E10,DWG_TITLES!A:B,2,FALSE) -> MATERIAL LIST OF CABLE TRAYS, MCT AND SUPPORTS - ELE/INS/TEL- BLOCK 01
A11: 45358 | B11: EIT | C11: LIS-H22-321-001-A | D11: DETALHADO | E11: =LEFT(C11,15) -> LIS-H22-321-001 | F11: =VLOOKUP(E11,DWG_TITLES!A:B,2,FALSE) -> MATERIAL LIST OF CABLE TRAYS, MCT AND SUPPORTS - ELE/INS/TEL- BLOCK 01
A12: 45357 | B12: EIT | C12: LIS-H22-321-001-B | D12: DETALHADO | E12: =LEFT(C12,15) -> LIS-H22-321-001 | F12: =VLOOKUP(E12,DWG_TITLES!A:B,2,FALSE) -> MATERIAL LIST OF CABLE TRAYS, MCT AND SUPPORTS - ELE/INS/TEL- BLOCK 01
... A212: 45406 | B212: OUTFITTING | C212: 831-H22-610-001-B | D212: BÁSICO | E212: =LEFT(C212,15) -> 831-H22-610-001 | F212: =VLOOKUP(E212,DWG_TITLES!A:B,2,FALSE) -> CANCELADO - OUTFITTING MATERIAL TAKE-OFF (MTO)
A213: 45684 | B213: EIT | C213: 832-7-H22-331-500-0 | D213: BÁSICO | E213: =LEFT(C213,17) -> 832-7-H22-331-500 | F213: =VLOOKUP(E213,DWG_TITLES!A:B,2,FALSE) -> CANCELADO - MATERIAL REQUISITION OF LIGHTING FIXTURES (ALL LIGHT INCLUDED IN THE LIGHTING LINE DIAGRAMS)
A214: 45684 | B214: EIT | C214: 832-7-H22-331-500-A | D214: BÁSICO | E214: =LEFT(C214,17) -> 832-7-H22-331-500 | F214: =VLOOKUP(E214,DWG_TITLES!A:B,2,FALSE) -> CANCELADO - MATERIAL REQUISITION OF LIGHTING FIXTURES (ALL LIGHT INCLUDED IN THE LIGHTING LINE DIAGRAMS)
A215: 45770 | B215: EIT | C215: 832-7-H22-331-500-B | D215: BÁSICO | E215: =LEFT(C215,17) -> 832-7-H22-331-500 | F215: =VLOOKUP(E215,DWG_TITLES!A:B,2,FALSE) -> CANCELADO - MATERIAL REQUISITION OF LIGHTING FIXTURES (ALL LIGHT INCLUDED IN THE LIGHTING LINE DIAGRAMS)
A216: 45796 | B216: EIT | C216: 832-7-H22-331-500-C | D216: BÁSICO | E216: =LEFT(C216,17) -> 832-7-H22-331-500 | F216: =VLOOKUP(E216,DWG_TITLES!A:B,2,FALSE) -> CANCELADO - MATERIAL REQUISITION OF LIGHTING FIXTURES (ALL LIGHT INCLUDED IN THE LIGHTING LINE DIAGRAMS)
A217: 45798 | B217: EIT | C217: 832-7-H22-331-500-D | D217: BÁSICO | E217: =LEFT(C217,17) -> 832-7-H22-331-500 | F217: =VLOOKUP(E217,DWG_TITLES!A:B,2,FALSE) -> CANCELADO - MATERIAL REQUISITION OF LIGHTING FIXTURES (ALL LIGHT INCLUDED IN THE LIGHTING LINE DIAGRAMS)
A218: 45834 | B218: EIT | C218: 832-7-H22-331-500-E | D218: BÁSICO | E218: =LEFT(C218,17) -> 832-7-H22-331-500 | F218: =VLOOKUP(E218,DWG_TITLES!A:B,2,FALSE) -> CANCELADO - MATERIAL REQUISITION OF LIGHTING FIXTURES (ALL LIGHT INCLUDED IN THE LIGHTING LINE DIAGRAMS)
A219: 45902 | B219: EIT | C219: 832-7-H22-331-500-F | D219: BÁSICO | E219: =LEFT(C219,17) -> 832-7-H22-331-500 | F219: =VLOOKUP(E219,DWG_TITLES!A:B,2,FALSE) -> CANCELADO - MATERIAL REQUISITION OF LIGHTING FIXTURES (ALL LIGHT INCLUDED IN THE LIGHTING LINE DIAGRAMS)
A220: 46042 | B220: EIT | C220: 832-7-H22-331-500-G | D220: BÁSICO | E220: =LEFT(C220,17) -> 832-7-H22-331-500 | F220: =VLOOKUP(E220,DWG_TITLES!A:B,2,FALSE) -> CANCELADO - MATERIAL REQUISITION OF LIGHTING FIXTURES (ALL LIGHT INCLUDED IN THE LIGHTING LINE DIAGRAMS)
A221: 46266 | B221: EIT | C221: LIS-H22-300-700-A | D221: BÁSICO | E221: =LEFT(C221,15) -> LIS-H22-300-700 | F221: =VLOOKUP(E221,DWG_TITLES!A:B,2,FALSE) -> CANCELADO - MTO - MATERIAL DE CALHAS E SUPORTES ELÉTRICOS - ROTA SECUNDÁRIA
A222: 46157 | B222: EIT | C222: LIS-H22-300-701-0 | D222: BÁSICO | E222: =LEFT(C222,15) -> LIS-H22-300-701 | F222: =VLOOKUP(E222,DWG_TITLES!A:B,2,FALSE) -> MTO – MATERIAIS AUXILIARES PARA INSTALAÇÃO ELÉTRICA
A223: 46220 | B223: EIT | C223: LIS-H22-300-701-A | D223: BÁSICO | E223: =LEFT(C223,15) -> LIS-H22-300-701 | F223: =VLOOKUP(E223,DWG_TITLES!A:B,2,FALSE) -> MTO – MATERIAIS AUXILIARES PARA INSTALAÇÃO ELÉTRICA
A224: 45840 | B224: EIT | C224: LIS-H22-304-502-0 | D224: BÁSICO | E224: =LEFT(C224,15) -> LIS-H22-304-502 | F224: =VLOOKUP(E224,DWG_TITLES!A:B,2,FALSE) -> CANCELADO - MATERIAL REQUISITON OF CABLE GLANDS - ELE
A225: 46038 | B225: EIT | C225: LIS-H22-304-502-A | D225: BÁSICO | E225: =LEFT(C225,15) -> LIS-H22-304-502 | F225: =VLOOKUP(E225,DWG_TITLES!A:B,2,FALSE) -> CANCELADO - MATERIAL REQUISITON OF CABLE GLANDS - ELE
A226: 46230 | B226: EIT | C226: LIS-H22-304-502-B | D226: BÁSICO | E226: =LEFT(C226,15) -> LIS-H22-304-502 | F226: =VLOOKUP(E226,DWG_TITLES!A:B,2,FALSE) -> CANCELADO - MATERIAL REQUISITON OF CABLE GLANDS - ELE
A227: 46283 | B227: EIT | C227: LIS-H22-304-502-C | D227: BÁSICO | E227: =LEFT(C227,15) -> LIS-H22-304-502 | F227: =VLOOKUP(E227,DWG_TITLES!A:B,2,FALSE) -> CANCELADO - MATERIAL REQUISITON OF CABLE GLANDS - ELE
A228: 45840 | B228: EIT | C228: LIS-H22-304-503-0 | D228: BÁSICO | E228: =LEFT(C228,15) -> LIS-H22-304-503 | F228: =VLOOKUP(E228,DWG_TITLES!A:B,2,FALSE) -> CANCELADO - MATERIAL REQUISITON OF CABLE GLANDS - INS
A229: 46038 | B229: EIT | C229: LIS-H22-304-503-A | D229: BÁSICO | E229: =LEFT(C229,15) -> LIS-H22-304-503 | F229: =VLOOKUP(E229,DWG_TITLES!A:B,2,FALSE) -> CANCELADO - MATERIAL REQUISITON OF CABLE GLANDS - INS
A230: 46230 | B230: EIT | C230: LIS-H22-304-503-B | D230: BÁSICO | E230: =LEFT(C230,15) -> LIS-H22-304-503 | F230: =VLOOKUP(E230,DWG_TITLES!A:B,2,FALSE) -> CANCELADO - MATERIAL REQUISITON OF CABLE GLANDS - INS
A231: 46283 | B231: EIT | C231: LIS-H22-304-503-C | D231: BÁSICO | E231: =LEFT(C231,15) -> LIS-H22-304-503 | F231: =VLOOKUP(E231,DWG_TITLES!A:B,2,FALSE) -> CANCELADO - MATERIAL REQUISITON OF CABLE GLANDS - INS
A232: 45840 | B232: EIT | C232: LIS-H22-304-504-0 | D232: BÁSICO | E232: =LEFT(C232,15) -> LIS-H22-304-504 | F232: =VLOOKUP(E232,DWG_TITLES!A:B,2,FALSE) -> CANCELADO - MATERIAL REQUISITON OF CABLE GLANDS - TEL
... A280: 46087 | B280: TUBULAÇÃO | C280: LIS-H22-500-060-A | D280: BÁSICO | E280: =LEFT(C280,15) -> LIS-H22-500-060 | F280: =VLOOKUP(E280,DWG_TITLES!A:B,2,FALSE) -> SCUPPER LIST

Sheet MTO_EN
A1: 46007 | B1: =VLOOKUP(MTO_PT!B1,LANG!A:B,2,FALSE) -> EIT | C1: 831-H22-300-063-0 | D1: =VLOOKUP(MTO_PT!D1,LANG!A:B,2,FALSE) -> DETAILED | E1: 831-H22-300-063 | F1: MATERIAL LIST OF MCTs - SEALING MODULES
A2: 46030 | B2: =VLOOKUP(MTO_PT!B2,LANG!A:B,2,FALSE) -> EIT | C2: 831-H22-300-063-A | D2: =VLOOKUP(MTO_PT!D2,LANG!A:B,2,FALSE) -> DETAILED | E2: 831-H22-300-063 | F2: MATERIAL LIST OF MCTs - SEALING MODULES
A3: 46063 | B3: =VLOOKUP(MTO_PT!B3,LANG!A:B,2,FALSE) -> EIT | C3: 831-H22-300-063-B | D3: =VLOOKUP(MTO_PT!D3,LANG!A:B,2,FALSE) -> DETAILED | E3: 831-H22-300-063 | F3: MATERIAL LIST OF MCTs - SEALING MODULES
A4: 46120 | B4: =VLOOKUP(MTO_PT!B4,LANG!A:B,2,FALSE) -> EIT | C4: 831-H22-300-063-C | D4: =VLOOKUP(MTO_PT!D4,LANG!A:B,2,FALSE) -> DETAILED | E4: 831-H22-300-063 | F4: MATERIAL LIST OF MCTs - SEALING MODULES
A5: 46219 | B5: =VLOOKUP(MTO_PT!B5,LANG!A:B,2,FALSE) -> EIT | C5: 831-H22-300-063-D | D5: =VLOOKUP(MTO_PT!D5,LANG!A:B,2,FALSE) -> DETAILED | E5: 831-H22-300-063 | F5: MATERIAL LIST OF MCTs - SEALING MODULES
A6: 46241 | B6: =VLOOKUP(MTO_PT!B6,LANG!A:B,2,FALSE) -> EIT | C6: EST-H22-300-501-0 | D6: =VLOOKUP(MTO_PT!D6,LANG!A:B,2,FALSE) -> DETAILED | E6: EST-H22-300-501 | F6: OVERALL INSTRUMENT LIST
A7: 46156 | B7: =VLOOKUP(MTO_PT!B7,LANG!A:B,2,FALSE) -> MECHANICAL | C7: LIS-H22-180-001-0 | D7: =VLOOKUP(MTO_PT!D7,LANG!A:B,2,FALSE) -> DETAILED | E7: LIS-H22-180-001 | F7: LISTA DE MATERIAIS PARA ELEMENTOS DE FIXAÇÃO PARA EQUIPAMENTOS MECÂNICOS
A8: 46205 | B8: =VLOOKUP(MTO_PT!B8,LANG!A:B,2,FALSE) -> MECHANICAL | C8: LIS-H22-180-001-A | D8: =VLOOKUP(MTO_PT!D8,LANG!A:B,2,FALSE) -> DETAILED | E8: LIS-H22-180-001 | F8: LISTA DE MATERIAIS PARA ELEMENTOS DE FIXAÇÃO PARA EQUIPAMENTOS MECÂNICOS
A9: 46205 | B9: =VLOOKUP(MTO_PT!B9,LANG!A:B,2,FALSE) -> MECHANICAL | C9: LIS-H22-180-001-B | D9: =VLOOKUP(MTO_PT!D9,LANG!A:B,2,FALSE) -> DETAILED | E9: LIS-H22-180-001 | F9: LISTA DE MATERIAIS PARA ELEMENTOS DE FIXAÇÃO PARA EQUIPAMENTOS MECÂNICOS
A10: 45162 | B10: =VLOOKUP(MTO_PT!B10,LANG!A:B,2,FALSE) -> EIT | C10: LIS-H22-321-001-0 | D10: =VLOOKUP(MTO_PT!D10,LANG!A:B,2,FALSE) -> DETAILED | E10: LIS-H22-321-001 | F10: MATERIAL LIST OF CABLE TRAYS, MCT AND SUPPORTS - ELE/INS/TEL- BLOCK 01
A11: 45358 | B11: =VLOOKUP(MTO_PT!B11,LANG!A:B,2,FALSE) -> EIT | C11: LIS-H22-321-001-A | D11: =VLOOKUP(MTO_PT!D11,LANG!A:B,2,FALSE) -> DETAILED | E11: LIS-H22-321-001 | F11: MATERIAL LIST OF CABLE TRAYS, MCT AND SUPPORTS - ELE/INS/TEL- BLOCK 01
A12: 45357 | B12: =VLOOKUP(MTO_PT!B12,LANG!A:B,2,FALSE) -> EIT | C12: LIS-H22-321-001-B | D12: =VLOOKUP(MTO_PT!D12,LANG!A:B,2,FALSE) -> DETAILED | E12: LIS-H22-321-001 | F12: MATERIAL LIST OF CABLE TRAYS, MCT AND SUPPORTS - ELE/INS/TEL- BLOCK 01
... A280: 46087 | B280: =VLOOKUP(MTO_PT!B280,LANG!A:B,2,FALSE) -> PIPING | C280: LIS-H22-500-060-A | D280: =VLOOKUP(MTO_PT!D280,LANG!A:B,2,FALSE) -> BASIC | E280: LIS-H22-500-060 | F280: SCUPPER LIST

Sheet TPS_PT
A1: 46163 | B1: EIT | C1: 832-7-H22-063-001-0 | D1: BÁSICO | E1: =LEFT(C1,LEN(C1)-2) -> 832-7-H22-063-001 | F1: =VLOOKUP(E1,DWG_TITLES!A:B,2,FALSE) -> ACQUISITION SPECIFICATION OF CABLE REEL
A2: 46230 | B2: EIT | C2: 832-7-H22-063-001-A | D2: BÁSICO | E2: =LEFT(C2,LEN(C2)-2) -> 832-7-H22-063-001 | F2: =VLOOKUP(E2,DWG_TITLES!A:B,2,FALSE) -> ACQUISITION SPECIFICATION OF CABLE REEL
A3: 45000 | B3: ELÉTRICA | C3: 832-7-H22-123-001-0 | D3: BÁSICO | E3: =LEFT(C3,LEN(C3)-2) -> 832-7-H22-123-001 | F3: =VLOOKUP(E3,DWG_TITLES!A:B,2,FALSE) -> ACQUISITION SPECIFICATION - REMOTE TANK LEVEL TRANSMITTER
A4: 45029 | B4: ELÉTRICA | C4: 832-7-H22-123-001-A | D4: BÁSICO | E4: =LEFT(C4,LEN(C4)-2) -> 832-7-H22-123-001 | F4: =VLOOKUP(E4,DWG_TITLES!A:B,2,FALSE) -> ACQUISITION SPECIFICATION - REMOTE TANK LEVEL TRANSMITTER
A5: 45076 | B5: ELÉTRICA | C5: 832-7-H22-123-001-B | D5: BÁSICO | E5: =LEFT(C5,LEN(C5)-2) -> 832-7-H22-123-001 | F5: =VLOOKUP(E5,DWG_TITLES!A:B,2,FALSE) -> ACQUISITION SPECIFICATION - REMOTE TANK LEVEL TRANSMITTER
A6: 45105 | B6: ELÉTRICA | C6: 832-7-H22-123-001-C | D6: BÁSICO | E6: =LEFT(C6,LEN(C6)-2) -> 832-7-H22-123-001 | F6: =VLOOKUP(E6,DWG_TITLES!A:B,2,FALSE) -> ACQUISITION SPECIFICATION - REMOTE TANK LEVEL TRANSMITTER
A7: 45128 | B7: ELÉTRICA | C7: 832-7-H22-123-001-D | D7: BÁSICO | E7: =LEFT(C7,LEN(C7)-2) -> 832-7-H22-123-001 | F7: =VLOOKUP(E7,DWG_TITLES!A:B,2,FALSE) -> ACQUISITION SPECIFICATION - REMOTE TANK LEVEL TRANSMITTER
A8: 46080 | B8: ELÉTRICA | C8: 832-7-H22-123-001-F | D8: BÁSICO | E8: =LEFT(C8,LEN(C8)-2) -> 832-7-H22-123-001 | F8: =VLOOKUP(E8,DWG_TITLES!A:B,2,FALSE) -> ACQUISITION SPECIFICATION - REMOTE TANK LEVEL TRANSMITTER
A9: 45236 | B9: ELÉTRICA | C9: 832-7-H22-123-002-0 | D9: BÁSICO | E9: =LEFT(C9,LEN(C9)-2) -> 832-7-H22-123-002 | F9: =VLOOKUP(E9,DWG_TITLES!A:B,2,FALSE) -> TECHNICAL BID EVALUATION - REMOTE TANK LEVEL TRANSMITTER
A10: 45239 | B10: ELÉTRICA | C10: 832-7-H22-123-002-B | D10: BÁSICO | E10: =LEFT(C10,LEN(C10)-2) -> 832-7-H22-123-002 | F10: =VLOOKUP(E10,DWG_TITLES!A:B,2,FALSE) -> TECHNICAL BID EVALUATION - REMOTE TANK LEVEL TRANSMITTER
A11: 44959 | B11: ARQUITETURA | C11: 832-7-H22-160-001-0 | D11: BÁSICO | E11: =LEFT(C11,LEN(C11)-2) -> 832-7-H22-160-001 | F11: =VLOOKUP(E11,DWG_TITLES!A:B,2,FALSE) -> ACQUISITION SPECIFICATION - HELIDECK SAFETY NET
A12: 44960 | B12: ARQUITETURA | C12: 832-7-H22-160-001-A | D12: BÁSICO | E12: =LEFT(C12,LEN(C12)-2) -> 832-7-H22-160-001 | F12: =VLOOKUP(E12,DWG_TITLES!A:B,2,FALSE) -> ACQUISITION SPECIFICATION - HELIDECK SAFETY NET
... A720: 45523 | B720: MECÂNICA | C720: 832-7-H22-850-001-G | D720: BÁSICO | E720: =LEFT(C720,LEN(C720)-2) -> 832-7-H22-850-001 | F720: =VLOOKUP(E720,DWG_TITLES!A:B,2,FALSE) -> CANCELADO - PIPING SPECIFICATION

Sheet TPS_EN
A1: 46163 | B1: =VLOOKUP(TPS_PT!B1,LANG!A:B,2,FALSE) -> EIT | C1: 832-7-H22-063-001-0 | D1: =VLOOKUP(TPS_PT!D1,LANG!A:B,2,FALSE) -> BASIC | E1: =LEFT(C1,LEN(C1)-2) -> 832-7-H22-063-001 | F1: =VLOOKUP(E1,DWG_TITLES!A:B,2,FALSE) -> ACQUISITION SPECIFICATION OF CABLE REEL
A2: 46230 | B2: =VLOOKUP(TPS_PT!B2,LANG!A:B,2,FALSE) -> EIT | C2: 832-7-H22-063-001-A | D2: =VLOOKUP(TPS_PT!D2,LANG!A:B,2,FALSE) -> BASIC | E2: =LEFT(C2,LEN(C2)-2) -> 832-7-H22-063-001 | F2: =VLOOKUP(E2,DWG_TITLES!A:B,2,FALSE) -> ACQUISITION SPECIFICATION OF CABLE REEL
A3: 45000 | B3: =VLOOKUP(TPS_PT!B3,LANG!A:B,2,FALSE) -> ELECTRICAL | C3: 832-7-H22-123-001-0 | D3: =VLOOKUP(TPS_PT!D3,LANG!A:B,2,FALSE) -> BASIC | E3: =LEFT(C3,LEN(C3)-2) -> 832-7-H22-123-001 | F3: =VLOOKUP(E3,DWG_TITLES!A:B,2,FALSE) -> ACQUISITION SPECIFICATION - REMOTE TANK LEVEL TRANSMITTER
A4: 45029 | B4: =VLOOKUP(TPS_PT!B4,LANG!A:B,2,FALSE) -> ELECTRICAL | C4: 832-7-H22-123-001-A | D4: =VLOOKUP(TPS_PT!D4,LANG!A:B,2,FALSE) -> BASIC | E4: =LEFT(C4,LEN(C4)-2) -> 832-7-H22-123-001 | F4: =VLOOKUP(E4,DWG_TITLES!A:B,2,FALSE) -> ACQUISITION SPECIFICATION - REMOTE TANK LEVEL TRANSMITTER
A5: 45076 | B5: =VLOOKUP(TPS_PT!B5,LANG!A:B,2,FALSE) -> ELECTRICAL | C5: 832-7-H22-123-001-B | D5: =VLOOKUP(TPS_PT!D5,LANG!A:B,2,FALSE) -> BASIC | E5: =LEFT(C5,LEN(C5)-2) -> 832-7-H22-123-001 | F5: =VLOOKUP(E5,DWG_TITLES!A:B,2,FALSE) -> ACQUISITION SPECIFICATION - REMOTE TANK LEVEL TRANSMITTER
A6: 45105 | B6: =VLOOKUP(TPS_PT!B6,LANG!A:B,2,FALSE) -> ELECTRICAL | C6: 832-7-H22-123-001-C | D6: =VLOOKUP(TPS_PT!D6,LANG!A:B,2,FALSE) -> BASIC | E6: =LEFT(C6,LEN(C6)-2) -> 832-7-H22-123-001 | F6: =VLOOKUP(E6,DWG_TITLES!A:B,2,FALSE) -> ACQUISITION SPECIFICATION - REMOTE TANK LEVEL TRANSMITTER
A7: 45128 | B7: =VLOOKUP(TPS_PT!B7,LANG!A:B,2,FALSE) -> ELECTRICAL | C7: 832-7-H22-123-001-D | D7: =VLOOKUP(TPS_PT!D7,LANG!A:B,2,FALSE) -> BASIC | E7: =LEFT(C7,LEN(C7)-2) -> 832-7-H22-123-001 | F7: =VLOOKUP(E7,DWG_TITLES!A:B,2,FALSE) -> ACQUISITION SPECIFICATION - REMOTE TANK LEVEL TRANSMITTER
A8: 46080 | B8: =VLOOKUP(TPS_PT!B8,LANG!A:B,2,FALSE) -> ELECTRICAL | C8: 832-7-H22-123-001-F | D8: =VLOOKUP(TPS_PT!D8,LANG!A:B,2,FALSE) -> BASIC | E8: =LEFT(C8,LEN(C8)-2) -> 832-7-H22-123-001 | F8: =VLOOKUP(E8,DWG_TITLES!A:B,2,FALSE) -> ACQUISITION SPECIFICATION - REMOTE TANK LEVEL TRANSMITTER
A9: 45236 | B9: =VLOOKUP(TPS_PT!B9,LANG!A:B,2,FALSE) -> ELECTRICAL | C9: 832-7-H22-123-002-0 | D9: =VLOOKUP(TPS_PT!D9,LANG!A:B,2,FALSE) -> BASIC | E9: =LEFT(C9,LEN(C9)-2) -> 832-7-H22-123-002 | F9: =VLOOKUP(E9,DWG_TITLES!A:B,2,FALSE) -> TECHNICAL BID EVALUATION - REMOTE TANK LEVEL TRANSMITTER
A10: 45239 | B10: =VLOOKUP(TPS_PT!B10,LANG!A:B,2,FALSE) -> ELECTRICAL | C10: 832-7-H22-123-002-B | D10: =VLOOKUP(TPS_PT!D10,LANG!A:B,2,FALSE) -> BASIC | E10: =LEFT(C10,LEN(C10)-2) -> 832-7-H22-123-002 | F10: =VLOOKUP(E10,DWG_TITLES!A:B,2,FALSE) -> TECHNICAL BID EVALUATION - REMOTE TANK LEVEL TRANSMITTER
A11: 44959 | B11: =VLOOKUP(TPS_PT!B11,LANG!A:B,2,FALSE) -> ARCHITECTURE | C11: 832-7-H22-160-001-0 | D11: =VLOOKUP(TPS_PT!D11,LANG!A:B,2,FALSE) -> BASIC | E11: =LEFT(C11,LEN(C11)-2) -> 832-7-H22-160-001 | F11: =VLOOKUP(E11,DWG_TITLES!A:B,2,FALSE) -> ACQUISITION SPECIFICATION - HELIDECK SAFETY NET
A12: 44960 | B12: =VLOOKUP(TPS_PT!B12,LANG!A:B,2,FALSE) -> ARCHITECTURE | C12: 832-7-H22-160-001-A | D12: =VLOOKUP(TPS_PT!D12,LANG!A:B,2,FALSE) -> BASIC | E12: =LEFT(C12,LEN(C12)-2) -> 832-7-H22-160-001 | F12: =VLOOKUP(E12,DWG_TITLES!A:B,2,FALSE) -> ACQUISITION SPECIFICATION - HELIDECK SAFETY NET
... A720: 45523 | B720: =VLOOKUP(TPS_PT!B720,LANG!A:B,2,FALSE) -> MECHANICAL | C720: 832-7-H22-850-001-G | D720: =VLOOKUP(TPS_PT!D720,LANG!A:B,2,FALSE) -> BASIC | E720: =LEFT(C720,LEN(C720)-2) -> 832-7-H22-850-001 | F720: =VLOOKUP(E720,DWG_TITLES!A:B,2,FALSE) -> CANCELADO - PIPING SPECIFICATION

Sheet DWG_TITLES
A2: 831-H22-314-003 | B2: 24VDC DISTRIBUTION SYSTEM DIAGRAM
A3: 831-H22-623-002 | B3: ACCOMODATION LADDERS
A4: 831-H22-673-002 | B4: AFT CARGO HANDLING AND ARRANGEMENTS
A5: 831-H22-110-004 | B5: AFT END STRUCTURE
A6: 831-H22-601-002 | B6: AIR DEPT OFFICE ARRANGEMENT
A7: 831-H22-512-002 | B7: AIR INTAKE SYSTEM DIAGRAM
A8: EST-H22-073-001 | B8: AIRBORNE NOISE ESTIMATE
A9: 831-H22-581-001 | B9: ANCHORING SYSTEM ARRANGEMENT
A10: EST-H22-633-002 | B10: ARC FLASH ANALYSIS
A11: 831-H22-542-003 | B11: AVIATION FUEL SYSTEM DIAGRAM
A12: 831-H22-665-003 | B12: AVIATION WORKSHOP ARRANGEMENT
A13: EST-H22-835-001 | B13: BASELINE WEIGHT ESTIMATE
... A10484: ADP-E0332-0182 | B10484: MAQUETE 3D DO NAVIO EM NAVISWORKS

Sheet LANG
A1: PT | B1: EN
A2: ESTRUTURA | B2: STRUCTURE
A3: MECÂNICA | B3: MECHANICAL
A4: OUTFITTING | B4: OUTFITTING
A5: ELÉTRICA | B5: ELECTRICAL
A6: EIT | B6: EIT
A7: TUBULAÇÃO | B7: PIPING
A8: ARQUITETURA | B8: ARCHITECTURE
A9: INSTRUMENTAÇÃO | B9: INSTRUMENTATION
A10: GERAL | B10: GERAL
A11: HVAC | B11: HVAC
A12: BÁSICO | B12: BASIC
... A18: NÃO APROVADO | B18: NOT APPROVED
